2020-09-28 22:19:06,805 ERROR: Exception on /user/Bernard [GET] [in g:\my drive\code\microblog\venv\lib\site-packages\flask\app.py:1891]
Traceback (most recent call last):
  File "g:\my drive\code\microblog\venv\lib\site-packages\flask\app.py", line 2447, in wsgi_app
    response = self.full_dispatch_request()
  File "g:\my drive\code\microblog\venv\lib\site-packages\flask\app.py", line 1952, in full_dispatch_request
    rv = self.handle_user_exception(e)
  File "g:\my drive\code\microblog\venv\lib\site-packages\flask\app.py", line 1821, in handle_user_exception
    reraise(exc_type, exc_value, tb)
  File "g:\my drive\code\microblog\venv\lib\site-packages\flask\_compat.py", line 39, in reraise
    raise value
  File "g:\my drive\code\microblog\venv\lib\site-packages\flask\app.py", line 1950, in full_dispatch_request
    rv = self.dispatch_request()
  File "g:\my drive\code\microblog\venv\lib\site-packages\flask\app.py", line 1936, in dispatch_request
    return self.view_functions[rule.endpoint](**req.view_args)
  File "g:\my drive\code\microblog\venv\lib\site-packages\flask_login\utils.py", line 272, in decorated_view
    return func(*args, **kwargs)
  File "G:\My Drive\code\microblog\app\routes.py", line 96, in user
    form = EmptyForm()
NameError: name 'EmptyForm' is not defined
2020-09-28 22:19:26,550 ERROR: Exception on /user/Bernard [GET] [in g:\my drive\code\microblog\venv\lib\site-packages\flask\app.py:1891]
Traceback (most recent call last):
  File "g:\my drive\code\microblog\venv\lib\site-packages\flask\app.py", line 2447, in wsgi_app
    response = self.full_dispatch_request()
  File "g:\my drive\code\microblog\venv\lib\site-packages\flask\app.py", line 1952, in full_dispatch_request
    rv = self.handle_user_exception(e)
  File "g:\my drive\code\microblog\venv\lib\site-packages\flask\app.py", line 1821, in handle_user_exception
    reraise(exc_type, exc_value, tb)
  File "g:\my drive\code\microblog\venv\lib\site-packages\flask\_compat.py", line 39, in reraise
    raise value
  File "g:\my drive\code\microblog\venv\lib\site-packages\flask\app.py", line 1950, in full_dispatch_request
    rv = self.dispatch_request()
  File "g:\my drive\code\microblog\venv\lib\site-packages\flask\app.py", line 1936, in dispatch_request
    return self.view_functions[rule.endpoint](**req.view_args)
  File "g:\my drive\code\microblog\venv\lib\site-packages\flask_login\utils.py", line 272, in decorated_view
    return func(*args, **kwargs)
  File "G:\My Drive\code\microblog\app\routes.py", line 96, in user
    form = EmptyForm()
NameError: name 'EmptyForm' is not defined
2020-09-28 22:22:06,954 INFO: Microblog startup [in G:\My Drive\code\microblog\app\__init__.py:46]
2020-09-28 22:24:59,411 INFO: Microblog startup [in G:\My Drive\code\microblog\app\__init__.py:46]
2020-09-28 22:27:49,901 INFO: Microblog startup [in G:\My Drive\code\microblog\app\__init__.py:46]
2020-09-28 22:29:07,873 INFO: Microblog startup [in G:\My Drive\code\microblog\app\__init__.py:46]
2020-09-28 22:29:10,713 ERROR: Exception on /edit_profile [GET] [in g:\my drive\code\microblog\venv\lib\site-packages\flask\app.py:1891]
Traceback (most recent call last):
  File "g:\my drive\code\microblog\venv\lib\site-packages\flask\app.py", line 2447, in wsgi_app
    response = self.full_dispatch_request()
  File "g:\my drive\code\microblog\venv\lib\site-packages\flask\app.py", line 1952, in full_dispatch_request
    rv = self.handle_user_exception(e)
  File "g:\my drive\code\microblog\venv\lib\site-packages\flask\app.py", line 1821, in handle_user_exception
    reraise(exc_type, exc_value, tb)
  File "g:\my drive\code\microblog\venv\lib\site-packages\flask\_compat.py", line 39, in reraise
    raise value
  File "g:\my drive\code\microblog\venv\lib\site-packages\flask\app.py", line 1950, in full_dispatch_request
    rv = self.dispatch_request()
  File "g:\my drive\code\microblog\venv\lib\site-packages\flask\app.py", line 1936, in dispatch_request
    return self.view_functions[rule.endpoint](**req.view_args)
  File "g:\my drive\code\microblog\venv\lib\site-packages\flask_login\utils.py", line 272, in decorated_view
    return func(*args, **kwargs)
  File "G:\My Drive\code\microblog\app\routes.py", line 26, in edit_profile
    return render_template('edit_profile.html', title='Edit Profile',
  File "g:\my drive\code\microblog\venv\lib\site-packages\flask\templating.py", line 137, in render_template
    return _render(
  File "g:\my drive\code\microblog\venv\lib\site-packages\flask\templating.py", line 120, in _render
    rv = template.render(context)
  File "g:\my drive\code\microblog\venv\lib\site-packages\jinja2\environment.py", line 1090, in render
    self.environment.handle_exception()
  File "g:\my drive\code\microblog\venv\lib\site-packages\jinja2\environment.py", line 832, in handle_exception
    reraise(*rewrite_traceback_stack(source=source))
  File "g:\my drive\code\microblog\venv\lib\site-packages\jinja2\_compat.py", line 28, in reraise
    raise value.with_traceback(tb)
  File "G:\My Drive\code\microblog\app\templates\edit_profile.html", line 1, in top-level template code
    {% extends "base.html" %}
  File "G:\My Drive\code\microblog\app\templates\base.html", line 34, in top-level template code
    {% block content %}{% endblock %}
  File "G:\My Drive\code\microblog\app\templates\edit_profile.html", line 15, in block "content"
    {{ form.email.label }}<br>
  File "g:\my drive\code\microblog\venv\lib\site-packages\jinja2\environment.py", line 471, in getattr
    return getattr(obj, attribute)
jinja2.exceptions.UndefinedError: 'app.forms.EditProfileForm object' has no attribute 'email'
2020-09-28 22:31:33,046 INFO: Microblog startup [in G:\My Drive\code\microblog\app\__init__.py:46]
2020-09-28 22:31:39,427 ERROR: Exception on /edit_profile [GET] [in g:\my drive\code\microblog\venv\lib\site-packages\flask\app.py:1891]
Traceback (most recent call last):
  File "g:\my drive\code\microblog\venv\lib\site-packages\flask\app.py", line 2447, in wsgi_app
    response = self.full_dispatch_request()
  File "g:\my drive\code\microblog\venv\lib\site-packages\flask\app.py", line 1952, in full_dispatch_request
    rv = self.handle_user_exception(e)
  File "g:\my drive\code\microblog\venv\lib\site-packages\flask\app.py", line 1821, in handle_user_exception
    reraise(exc_type, exc_value, tb)
  File "g:\my drive\code\microblog\venv\lib\site-packages\flask\_compat.py", line 39, in reraise
    raise value
  File "g:\my drive\code\microblog\venv\lib\site-packages\flask\app.py", line 1950, in full_dispatch_request
    rv = self.dispatch_request()
  File "g:\my drive\code\microblog\venv\lib\site-packages\flask\app.py", line 1936, in dispatch_request
    return self.view_functions[rule.endpoint](**req.view_args)
  File "g:\my drive\code\microblog\venv\lib\site-packages\flask_login\utils.py", line 272, in decorated_view
    return func(*args, **kwargs)
  File "G:\My Drive\code\microblog\app\routes.py", line 27, in edit_profile
    form.email.data = current_user.email
AttributeError: 'EditProfileForm' object has no attribute 'email'
2020-09-28 22:37:52,717 INFO: Microblog startup [in G:\My Drive\code\microblog\app\__init__.py:46]
